Traceback (most recent call last):
  File "/home/tom/miniforge3/envs/gen_simpy/lib/python3.10/site-packages/jupyter_cache/executors/utils.py", line 58, in single_nb_execution
    executenb(
  File "/home/tom/miniforge3/envs/gen_simpy/lib/python3.10/site-packages/nbclient/client.py", line 1314, in execute
    return NotebookClient(nb=nb, resources=resources, km=km, **kwargs).execute()
  File "/home/tom/miniforge3/envs/gen_simpy/lib/python3.10/site-packages/jupyter_core/utils/__init__.py", line 165, in wrapped
    return loop.run_until_complete(inner)
  File "/home/tom/miniforge3/envs/gen_simpy/lib/python3.10/asyncio/base_events.py", line 649, in run_until_complete
    return future.result()
  File "/home/tom/miniforge3/envs/gen_simpy/lib/python3.10/site-packages/nbclient/client.py", line 709, in async_execute
    await self.async_execute_cell(
  File "/home/tom/miniforge3/envs/gen_simpy/lib/python3.10/site-packages/nbclient/client.py", line 1062, in async_execute_cell
    await self._check_raise_for_error(cell, cell_index, exec_reply)
  File "/home/tom/miniforge3/envs/gen_simpy/lib/python3.10/site-packages/nbclient/client.py", line 918, in _check_raise_for_error
    raise CellExecutionError.from_cell_and_msg(cell, exec_reply_content)
nbclient.exceptions.CellExecutionError: An error occurred while executing the following cell:
------------------
caption = "Table 1: Comparison of stroke capacity planning model outputs: stage 1 versus stage 2 " \
          "(internal replication). Figures are mean (sd)."
# ccu_summary = pd.read_csv("ccu_model_comparison.csv", index_col=['Study Stage', 
#                                                                  'metric'])
# ccu_summary = ccu_summary.style.set_caption(caption)
# ccu_summary
[asu_comparison](../../03_stroke/asu_comparison.png)
------------------


[0;36m  Cell [0;32mIn[2], line 7[0;36m[0m
[0;31m    [asu_comparison](../../03_stroke/asu_comparison.png)[0m
[0m                             ^[0m
[0;31mSyntaxError[0m[0;31m:[0m invalid decimal literal


